<mujoco model="allegro_assets">
<!-- Copyright (c) 2023 Boston Dynamics AI Institute LLC. All rights reserved. -->
  <!-- First finger -->
  <body name="ff_base" pos="0 0.0435 -0.001542" quat="0.999048 -0.0436194 0 0">
    <joint name="ffj0" class="base"/>
    <geom class="base_visual"/>
    <geom class="base_collision"/>
    <body name="ff_proximal" pos="0 0 0.0164">
      <joint name="ffj1" class="proximal"/>
      <geom class="proximal_visual"/>
      <geom class="proximal_collision"/>
      <body name="ff_medial" pos="0 0 0.054">
        <joint name="ffj2" class="medial"/>
        <geom class="medial_visual"/>
        <geom class="medial_collision"/>
        <body name="ff_distal" pos="0 0 0.0384">
          <joint name="ffj3" class="distal"/>
          <geom class="distal_visual"/>
          <geom class="distal_collision"/>
          <body name="ff_tip">
            <geom class="fingertip_visual"/>
            <geom class="fingertip_collision"/>
            <site pos="0 0 0" name="site_ff_tip"/>
          </body>
        </body>
      </body>
    </body>
  </body>
  <!-- Middle finger -->
  <body name="mf_base" pos="0 0 0.0007">
    <joint name="mfj0" class="base"/>
    <geom class="base_visual"/>
    <geom class="base_collision"/>
    <body name="mf_proximal" pos="0 0 0.0164">
      <joint name="mfj1" class="proximal"/>
      <geom class="proximal_visual"/>
      <geom class="proximal_collision"/>
      <body name="mf_medial" pos="0 0 0.054">
        <joint name="mfj2" class="medial"/>
        <geom class="medial_visual"/>
        <geom class="medial_collision"/>
        <body name="mf_distal" pos="0 0 0.0384">
          <joint name="mfj3" class="distal"/>
          <geom class="distal_visual"/>
          <geom class="distal_collision"/>
          <body name="mf_tip">
            <geom class="fingertip_visual"/>
            <geom class="fingertip_collision"/>
            <site pos="0 0 0" name="site_mf_tip"/>
          </body>
        </body>
      </body>
    </body>
  </body>
  <!-- Ring finger -->
  <body name="rf_base" pos="0 -0.0435 -0.001542" quat="0.999048 0.0436194 0 0">
    <joint name="rfj0" class="base"/>
    <geom class="base_visual"/>
    <geom class="base_collision"/>
    <body name="rf_proximal" pos="0 0 0.0164">
      <joint name="rfj1" class="proximal"/>
      <geom class="proximal_visual"/>
      <geom class="proximal_collision"/>
      <body name="rf_medial" pos="0 0 0.054">
        <joint name="rfj2" class="medial"/>
        <geom class="medial_visual"/>
        <geom class="medial_collision"/>
        <body name="rf_distal" pos="0 0 0.0384">
          <joint name="rfj3" class="distal"/>
          <geom class="distal_visual"/>
          <geom class="distal_collision"/>
          <body name="rf_tip">
            <geom class="fingertip_visual"/>
            <geom class="fingertip_collision"/>
            <site pos="0 0 0" name="site_rf_tip"/>
          </body>
        </body>
      </body>
    </body>
  </body>
  <!-- Thumb -->
  <body name="th_base" pos="-0.0182 0.019333 -0.045987" quat="0.477714 -0.521334 -0.521334 -0.477714">
    <joint name="thj0" class="thumb_base"/>
    <geom class="visual" mesh="link_12.0_right"/>
    <geom class="thumb_base_collision_0"/>
    <geom class="thumb_base_collision_1"/>
    <!-- This geometry is commented out, while we wait for MJX to support cylinder collisions. -->
    <!-- <geom class="thumb_base_collision_2"/> -->
    <body name="th_proximal" pos="-0.027 0.005 0.0399">
      <joint name="thj1" class="thumb_proximal"/>
      <geom class="visual" mesh="link_13.0"/>
      <geom class="thumb_proximal_collision"/>
      <body name="th_medial" pos="0 0 0.0177">
        <joint name="thj2" class="thumb_medial"/>
        <geom class="visual" mesh="link_14.0"/>
        <geom class="thumb_medial_collision"/>
        <body name="th_distal" pos="0 0 0.0514">
          <joint name="thj3" class="thumb_distal"/>
          <geom class="visual" mesh="link_15.0"/>
          <geom class="thumb_distal_collision"/>
          <body name="th_tip">
            <geom class="thumbtip_visual"/>
            <geom class="thumbtip_collision"/>
            <site pos="0 0 0" name="site_th_tip"/>
          </body>
        </body>
      </body>
    </body>
  </body>
</mujoco>
