<mujoco model="spot_arm">
<!-- Copyright (c) 2023 Boston Dynamics AI Institute LLC. All rights reserved. -->
    <body name="arm_link_sh0" pos="0.292 0 0.188" gravcomp="1">
      <joint name="arm_sh0" class="arm_sh0" type="hinge" axis="0 0 1" pos="0 0 0"/>
      <inertial mass="2.3364000000000003" diaginertia="0.009014303010689815 0.005835102417829581 0.00778747846359954" pos="-0.012372709810733795 -4.5211403630673885e-05 -0.02103196457028389" euler="0.0013490340912847287 -0.15433618253071657 0.0066354181456347305" />
      <geom name="arm_link_sh0_visual" class="visual" mesh="arm_link_sh0_visual" material="black"/>
      <geom name="arm_link_sh0_base" type="mesh" class="collision" mesh="arm_link_sh0_base"/>
      <geom name="arm_link_sh0_left_motor" type="mesh" class="collision" mesh="arm_link_sh0_left_motor"/>
      <geom name="arm_link_sh0_right_motor" type="mesh" class="collision" mesh="arm_link_sh0_right_motor"/>
      <site name="site_arm_link_sh0" pos="0 0 0" size="0.01"/>

      <body name="arm_link_sh1" pos="0 0 0" gravcomp="1">
        <joint name="arm_sh1" class="arm_sh1" type="hinge" axis="0 1 0" pos="0 0 0"/>
        <inertial mass="0.2596" diaginertia="6.312631747339145e-10 1.1487063558949979e-08 1.161105128440526e-08" pos="0.17047011852264404 -0.0019251034827902913 4.483893280848861e-05" euler="-0.01179850657706405 0.0002834144901480151 -0.02372295500868482" />
        <geom name="arm_link_sh1_visual" class="visual" mesh="arm_link_sh1_visual" material="yellow"/>
        <geom name="arm_link_sh1" type="mesh" class="collision" mesh="arm_link_sh1"/>
        <site name="site_arm_link_sh1" pos="0 0 0" size="0.01"/>

        <body name="arm_link_el0" pos="0.3385 0 0" gravcomp="1">
          <joint name="arm_el0" class="arm_el0" type="hinge" axis="0 1 0" pos="0 0 0"/>
          <inertial mass="0.725" diaginertia="0.0008215365829160558 0.0020047889807066404 0.0019722797759789395" pos="0.0553741455078125 0.00023603376757819206 0.04827198013663292" euler="-0.004185887288594259 -0.6136269547775202 -0.0004619387581783485" />
          <geom name="arm_link_el0_visual" class="visual" mesh="arm_link_el0_visual" material="black"/>
          <geom name="arm_link_el0" type="mesh" class="collision" mesh="arm_link_el0"/>
          <site name="site_arm_link_el0" pos="0 0 0" size="0.01"/>

          <body name="arm_link_el1" pos="0.40330 0.0 0.0750" gravcomp="1">
            <joint name="arm_el1" class="arm_el1" type="hinge" axis="1 0 0" pos="0 0 0"/>
            <inertial mass="0.725" diaginertia="0.0006254807525240598 0.004402454711936095 0.004515915146038191" pos="-0.1257835328578949 -0.013684478588402271 0.00010157923679798841" euler="-0.15027374227250867 -0.0007874585461915551 0.003728225436950172" />
            <geom name="arm_link_el1_visual" class="visual" mesh="arm_link_el1_visual" material="yellow"/>
            <geom name="arm_link_el1_main" type="mesh" class="collision" mesh="arm_link_el1_main"/>
            <geom name="arm_link_el1_lip" type="mesh" class="collision" mesh="arm_link_el1_lip"/>
            <site name="site_arm_link_el1" pos="0 0 0" size="0.01"/>

            <body name="arm_link_wr0" pos="0 0 0" gravcomp="1">
              <joint name="arm_wr0" class="arm_wr0" type="hinge" axis="0 1 0" pos="0 0 0"/>
              <inertial mass="0.98" diaginertia="0.0009851320696685427 0.0008916145765810678 0.0012354892751854467" pos="0.008210677653551102 -0.012051000259816647 3.143483627354726e-05" euler="-0.4951534907966386 0.0033720434077784134 0.020027599337697932" />
              <geom name="arm_link_wr0_visual" class="visual" mesh="arm_link_wr0_visual" material="black"/>
              <geom name="arm_link_wr0" type="mesh" class="collision" mesh="arm_link_wr0"/>
              <site name="site_arm_link_wr0" pos="0 0 0" size="0.01"/>

              <body name="arm_link_wr1" pos="0 0 0" gravcomp="1">
                <joint name="arm_wr1" class="arm_wr1" type="hinge" axis="1 0 0" pos="0 0 0"/>
                <inertial mass="0.785" diaginertia="0.00076741362048185 0.0017628124054271809 0.0016818105865345951" pos="0.12516802549362183 0.00010137435310753062 -0.013997982256114483" euler="0.006393076449033863 0.2928526604761865 -0.022814984050994802" />
                <geom name="arm_link_wr1_visual" class="visual" mesh="arm_link_wr1_visual" material="yellow"/>
                <geom name="arm_link_wr1" type="mesh" class="collision" mesh="arm_link_wr1"/>
                <geom name="front_jaw" type="mesh" class="collision" mesh="front_jaw"/>
                <geom name="middle_jaw" type="mesh" class="collision" mesh="middle_jaw"/>
                <geom name="jaw_tooth" type="mesh" class="collision" mesh="jaw_tooth"/>
                <site name="site_arm_link_wr1" pos="0 0 0" size="0.01"/>

                <body name="arm_link_fngr" pos="0.1174 0.0 0.0148" gravcomp="1">
                  <joint name="arm_f1x" class="arm_f1x" type="hinge" axis="0 1 0" pos="0 0 0"/>
                  <inertial mass="0.2" diaginertia="0.000144 0.000300 0.000391" pos="0.0478 -0.0002 -0.0163" euler="0.000342 0.375167 -0.004059" />
                  <geom name="arm_link_fngr_visual" class="visual" mesh="arm_link_fngr_visual" material="black"/>
                  <geom name="left_hinge" type="mesh" class="collision" mesh="left_hinge"/>
                  <geom name="left_finger" type="mesh" class="collision" mesh="left_finger"/>
                  <geom name="left_tooth" type="mesh" class="collision" mesh="left_tooth"/>
                  <geom name="right_hinge" type="mesh" class="collision" mesh="right_hinge"/>
                  <geom name="right_finger" type="mesh" class="collision" mesh="right_finger"/>
                  <geom name="right_tooth" type="mesh" class="collision" mesh="right_tooth"/>
                  <site name="site_arm_link_fngr" pos="0 0 0" size="0.01"/>
                </body>
              </body>
            </body>
          </body>
        </body>
      </body>
    </body>
</mujoco>
