<mujoco model="spot_arm">
<!-- Copyright (c) 2023 Boston Dynamics AI Institute LLC. All rights reserved. -->
<!-- fullinertia="M(1,1), M(2,2), M(3,3), M(1,2), M(1,3), M(2,3)" -->
  <body name="arm_link_sh0" pos="0.292 0 0.188" gravcomp="0">
    <joint name="arm_sh0" class="arm_sh0" type="hinge" axis="0 0 1" pos="0 0 0"/>
    <inertial mass="1.904699" fullinertia="0.008896 0.004922 0.0073030 0.000005 -0.000193 0.000033" pos="-0.008399 0.000272 -0.024603"/>
    <geom name="arm_link_sh0_visual" class="visual" mesh="arm_link_sh0_visual" material="black"/>
    <geom name="arm_link_sh0_base" class="collision" type="capsule" size="0.05 0.015" pos="0 0 -0.07"/>
    <geom name="arm_link_sh0_motor" class="collision" type="capsule" size="0.055 0.055" pos="-0.015 0 0" euler="1.57079632679 0 0"/>
    <!-- <geom name="arm_link_sh0_base" type="mesh" class="collision" mesh="arm_link_sh0_base"/> -->
    <!-- <geom name="arm_link_sh0_left_motor" type="mesh" class="collision" mesh="arm_link_sh0_left_motor"/> -->
    <!-- <geom name="arm_link_sh0_right_motor" type="mesh" class="collision" mesh="arm_link_sh0_right_motor"/> -->
    <site name="site_arm_link_sh0" pos="0 0 0" size="0.01"/>

    <body name="arm_link_sh1" pos="0 0 0" gravcomp="0">
      <joint name="arm_sh1" class="arm_sh1" type="hinge" axis="0 1 0" pos="0 0 0"/>
      <inertial mass="1.85701942" fullinertia="0.00261526 0.02703868 0.02819929 -0.00040406 0.00010019 0.00000547" pos="0.08084909 -0.00167243 0.00045644" />
      <geom name="arm_link_sh1_0_visual" class="visual" mesh="arm_link_sh1_0_visual" material="yellow"/>
      <geom name="arm_link_sh1_1_visual" class="visual" mesh="arm_link_sh1_1_visual" material="black"/>
      <geom name="arm_link_sh1" class="collision" type="capsule" size="0.04 0.175" pos="0.17 0 0" euler="0 1.57079632679 0"/>
      <!-- <geom name="arm_link_sh1" type="mesh" class="collision" mesh="arm_link_sh1"/> -->
      <site name="site_arm_link_sh1" pos="0 0 0" size="0.01"/>

      <body name="arm_link_el0" pos="0.3385 0 0" gravcomp="0">
        <joint name="arm_el0" class="arm_el0" type="hinge" axis="0 1 0" pos="0 0 0"/>
        <inertial mass="0.94831958" fullinertia="0.00175909 0.00269233 0.00202854 0.00006087  0.00092380 0.00005217" pos="0.04476621 -0.00271130 0.04991363" />
        <geom name="arm_link_el0_visual" class="visual" mesh="arm_link_el0_visual" material="black"/>
        <geom name="arm_link_el0_joint" class="collision" type="box" size="0.025 0.045 0.065" pos="0.02 0 0.04" euler= "0 0.5 0"/>
        <geom name="arm_link_el0_body" class="collision" type="capsule" size="0.045 0.025" pos="0.08 0 0.07" euler="0 1.57079632679 0"/>
        <!-- <geom name="arm_link_el0" type="mesh" class="collision" mesh="arm_link_el0"/> -->
        <site name="site_arm_link_el0" pos="0 0 0" size="0.01"/>

        <body name="arm_link_el1" pos="0.4033 0 0.075" gravcomp="0">
          <joint name="arm_el1" class="arm_el1" type="hinge" axis="1 0 0" pos="0 0 0"/>
          <inertial mass="1.01754820" fullinertia="0.00117710 0.01649389 0.01689901 -0.00260549 0.00000156 -0.00000287" pos="-0.16867073 -0.01616121 0.00001149" />
          <geom name="arm_link_el1_0_visual" class="visual" mesh="arm_link_el1_0_visual" material="yellow"/>
          <geom name="arm_link_el1_1_visual" class="visual" mesh="arm_link_el1_1_visual" material="black"/>
          <geom name="arm_link_el1" type="capsule" class="collision" size="0.035 0.095" pos="-0.15 0 0" euler="0 1.57079632679 0"/>
          <geom name="arm_link_el1_knob" type="sphere" class="collision" size="0.04" pos="0 -0.035 0"/>
          <!-- <geom name="arm_link_el1_main" type="mesh" class="collision" mesh="arm_link_el1_main"/> -->
          <!-- <geom name="arm_link_el1_lip" type="mesh" class="collision" mesh="arm_link_el1_lip"/> -->
          <site name="site_arm_link_el1" pos="0 0 0" size="0.01"/>

          <body name="arm_link_wr0" pos="0 0 0" gravcomp="0">
            <joint name="arm_wr0" class="arm_wr0" type="hinge" axis="0 1 0" pos="0 0 0"/>
            <inertial mass="0.58263740" fullinertia="0.00046738 0.00044968 0.00053616 0.00006957 0.00000040 0.00000016" pos="0.00952465 -0.01144406 0.00000186" />
            <geom name="arm_link_wr0_0_visual" class="visual" mesh="arm_link_wr0_0_visual" material="yellow"/>
            <geom name="arm_link_wr0_1_visual" class="visual" mesh="arm_link_wr0_1_visual" material="black"/>
            <geom name="arm_link_wr0" class="collision" type="capsule" size="0.035 0.04" pos="0.02 0 0" euler="0 1.57079632679 0"/>
            <!-- <geom name="arm_link_wr0" type="mesh" class="collision" mesh="arm_link_wr0"/> -->
            <site name="site_arm_link_wr0" pos="0 0 0" size="0.01"/>

            <body name="arm_link_wr1" pos="0 0 0" gravcomp="0">
              <joint name="arm_wr1" class="arm_wr1" type="hinge" axis="1 0 0" pos="0 0 0"/>
              <inertial mass="0.93335298" fullinertia="0.00098836 0.00197018 0.00165791 -0.00000126 -0.00036919 -0.00000074" pos="0.09751283 0.00009265 -0.01120523" />
              <geom name="arm_link_wr1_0_visual" class="visual" mesh="arm_link_wr1_0_visual" material="yellow"/>
              <geom name="arm_link_wr1_1_visual" class="visual" mesh="arm_link_wr1_1_visual" material="black"/>
              <geom name="arm_link_wr1" class="collision" type="box" size="0.03 0.04 0.0475" pos="0.11 0 -0.01" />
              <geom name="bottom_jaw" class="collision" type="box" size="0.03 0.025 0.01" pos="0.17 0 -0.0475" />
              <geom name="front_jaw" class="collision" type="box" size="0.016 0.015 0.01" pos="0.215 0 -0.0475" />
              <geom name="front_jaw_tooth" class="collision" type="box" size="0.005 0.01 0.005" pos="0.224 0 -0.039" euler="0 1 0"/>
              <!-- <geom name="arm_link_wr1" type="mesh" class="collision" mesh="arm_link_wr1"/> -->
              <!-- <geom name="front_jaw" type="mesh" class="collision" mesh="front_jaw"/> -->
              <!-- <geom name="middle_jaw" type="mesh" class="collision" mesh="middle_jaw"/> -->
              <!-- <geom name="jaw_tooth" type="mesh" class="collision" mesh="jaw_tooth"/> -->
              <site name="site_arm_link_wr1" pos="0 0 0" size="0.01"/>

              <body name="arm_link_fngr" pos="0.11745 0.0 0.014820" gravcomp="0">
                <joint name="arm_f1x" class="arm_f1x" type="hinge" axis="0 1 0" pos="0 0 0"/>
                <inertial mass="0.22383315" fullinertia="0.00025226 0.00048453 0.00059145 -0.00000536 -0.00015067 0.00000184" pos="0.03565178 0.00067200 -0.01227516" />
                <geom name="arm_link_fngr_0_visual" class="visual" mesh="arm_link_fngr_0_visual" material="yellow"/>
                <geom name="arm_link_fngr_1_visual" class="visual" mesh="arm_link_fngr_1_visual" material="black"/>
                <geom name="left_jaw" type="capsule" class="collision" size="0.015 0.06" pos="0.057 0.023 -0.023" euler="-0.45 2.0 0"/>
                <geom name="right_jaw" type="capsule" class="collision" size="0.015 0.06" pos="0.057 -0.023 -0.023" euler="0.45 2.0 0"/>
                <!-- <geom name="left_hinge" type="mesh" class="collision" mesh="left_hinge"/> -->
                <!-- <geom name="left_finger" type="mesh" class="collision" mesh="left_finger"/> -->
                <!-- <geom name="left_tooth" type="mesh" class="collision" mesh="left_tooth"/> -->
                <!-- <geom name="right_hinge" type="mesh" class="collision" mesh="right_hinge"/> -->
                <!-- <geom name="right_finger" type="mesh" class="collision" mesh="right_finger"/> -->
                <!-- <geom name="right_tooth" type="mesh" class="collision" mesh="right_tooth"/> -->
                <site name="site_arm_link_fngr" pos="0 0 0" size="0.01"/>
              </body>
            </body>
          </body>
        </body>
      </body>
    </body>
  </body>
</mujoco>
