<mujoco model="spot_sitting_box">
<!-- Copyright (c) 2023 Boston Dynamics AI Institute LLC. All rights reserved. -->
    <body name="front_left_hip" pos="0.29785 0.055 0" gravcomp="1.0">
        <inertial pos="-0.00537435 0.0128418 9.87523e-05" quat="0.636048 0.307541 -0.277812 0.650909" mass="1.68" diaginertia="0.00226544 0.00211474 0.00181296"/>
        <joint name="joint_front_left_hip_x" pos="0 0 0" axis="1 0 0" range="-0.785398 0.785398"/>
        <geom name="front_left_hip_visual" class="visual" mesh="front_left_hip_visual" material="black"/>
        <body name="front_left_upper_leg" pos="0 0.110945 0" gravcomp="1.0">
            <inertial pos="0.00514237 -0.00243237 -0.121009" quat="0.990951 -0.131467 -0.0256343 0.00871698" mass="2.34" diaginertia="0.0275596 0.0273549 0.00284815"/>
            <joint name="joint_front_left_hip_y" pos="0 0 0" axis="0 1 0" range="-0.898845 2.29511"/>
            <geom name="front_left_upper_leg_visual" class="visual" mesh="front_left_upper_leg_visual" material="yellow"/>
            <geom name="front_left_upper_leg" type="mesh" mesh="left_upper_leg_collision"/>
            <body name="front_left_lower_leg" pos="0.025 0 -0.3205" gravcomp="1.0">
                <inertial pos="0.00225794 4.6076e-05 -0.180082" quat="0.706982 -0.00596025 -0.00082302 0.707206" mass="0.35" diaginertia="0.00405032 0.00399902 0.00014934"/>
                <joint name="joint_front_left_knee" pos="0 0 0" axis="0 1 0" range="-2.7929 -0.2471"/>
                <geom name="front_left_lower_leg_visual" class="visual" mesh="front_left_lower_leg_visual" material="yellow"/>
                <geom name="front_left_lower_leg" type="mesh" mesh="left_lower_leg_collision"/>
                <geom size="0.036" pos="0 0 -0.3365"/>
                <site name="site_front_left" pos="0 0 0" size="0.01"/>
            </body>
        </body>
    </body>

    <body name="front_right_hip" pos="0.29785 -0.055 0" gravcomp="1.0">
        <inertial pos="-0.00537435 -0.0128418 -9.87523e-05" quat="0.277812 0.650909 -0.636048 0.307541" mass="1.68" diaginertia="0.00226544 0.00211474 0.00181296"/>
        <joint name="joint_front_right_hip_x" pos="0 0 0" axis="1 0 0" range="-0.785398 0.785398"/>
        <geom name="front_right_hip_visual" class="visual" mesh="front_right_hip_visual" material="black"/>
        <body name="front_right_upper_leg" pos="0 -0.110945 0" gravcomp="1.0">
            <inertial pos="0.00514237 0.00243237 -0.121009" quat="0.99095 0.131473 -0.0256344 -0.00871682" mass="2.34" diaginertia="0.0275596 0.0273549 0.00284815"/>
            <joint name="joint_front_right_hip_y" pos="0 0 0" axis="0 1 0" range="-0.898845 2.29511"/>
            <geom name="front_right_upper_leg_visual" class="visual" mesh="front_right_upper_leg_visual" material="yellow"/>
            <geom name="front_right_upper_leg" type="mesh" mesh="right_upper_leg_collision"/>
            <body name="front_right_lower_leg" pos="0.025 0 -0.3205" gravcomp="1.0">
                <inertial pos="0.00225794 4.6076e-05 -0.180082" quat="0.706982 -0.00596025 -0.00082302 0.707206" mass="0.35" diaginertia="0.00405032 0.00399902 0.00014934"/>
                <joint name="joint_front_right_knee" pos="0 0 0" axis="0 1 0" range="-2.7929 -0.2471"/>
                <geom name="front_right_lower_leg_visual" class="visual" mesh="front_right_lower_leg_visual" material="yellow"/>
                <geom name="front_right_lower_leg" type="mesh" mesh="right_lower_leg_collision"/>
                <geom size="0.036" pos="0 0 -0.3365"/>
                <site name="site_front_right" pos="0 0 0" size="0.01"/>
            </body>
        </body>
    </body>

    <body name="rear_left_hip" pos="-0.29785 0.055 0" euler="0.3 0 0">
        <inertial pos="-0.00537435 -0.0128418 -9.87523e-05" quat="0.277812 0.650909 -0.636048 0.307541" mass="1.68" diaginertia="0.00226544 0.00211474 0.00181296"/>
        <!-- <joint name="joint_rear_left_hip_x" pos="0 0 0" axis="1 0 0" range="-0.785398 0.785398"/> -->
        <geom name="rear_left_hip_visual" class="visual" mesh="rear_left_hip_visual" material="black"/>
        <body name="rear_left_upper_leg" pos="0 0.110945 0" euler="0 -0.349066 0">
            <inertial pos="0.00514237 -0.00243237 -0.121009" quat="0.990951 -0.131467 -0.0256343 0.00871698" mass="2.34" diaginertia="0.0275596 0.0273549 0.00284815"/>
            <!-- <joint name="joint_rear_left_hip_y" pos="0 0 0" axis="0 1 0" range="-0.898845 2.29511"/> -->
            <geom name="rear_left_upper_leg_visual" class="visual" mesh="rear_left_upper_leg_visual" material="yellow"/>
            <geom name="rear_left_upper_leg" type="mesh" mesh="left_upper_leg_collision"/>
            <body name="rear_left_lower_leg" pos="0.025 0 -0.3205" euler="0 -0.3 0">
                <inertial pos="0.00225794 4.6076e-05 -0.180082" quat="0.706982 -0.00596025 -0.00082302 0.707206" mass="0.35" diaginertia="0.00405032 0.00399902 0.00014934"/>
                <!-- <joint name="joint_rear_left_knee" pos="0 0 0" axis="0 1 0" range="-2.7929 -0.2471"/> -->
                <geom name="rear_left_lower_leg_visual" class="visual" mesh="rear_left_lower_leg_visual" material="yellow"/>
                <geom name="rear_left_lower_leg" type="mesh" mesh="left_lower_leg_collision"/>
                <geom size="0.036" pos="0 0 -0.3365"/>
                <site name="site_rear_left" pos="0 0 0" size="0.01"/>
            </body>
        </body>
    </body>

    <body name="rear_right_hip" pos="-0.29785 -0.055 0" euler="-0.3 0 0">
        <inertial pos="-0.00537435 -0.0128418 -9.87523e-05" quat="0.277812 0.650909 -0.636048 0.307541" mass="1.68" diaginertia="0.00226544 0.00211474 0.00181296"/>
        <!-- <joint name="joint_rear_right_hip_x" pos="0 0 0" axis="1 0 0" range="-0.785398 0.785398"/> -->
        <geom name="rear_right_hip_visual" class="visual" mesh="rear_right_hip_visual" material="black"/>
        <body name="rear_right_upper_leg" pos="0 -0.110945 0" euler="0 -0.349066 0">
            <inertial pos="0.00514237 0.00243237 -0.121009" quat="0.99095 0.131473 -0.0256344 -0.00871682" mass="2.34" diaginertia="0.0275596 0.0273549 0.00284815"/>
            <!-- <joint name="joint_rear_right_hip_y" pos="0 0 0" axis="0 1 0" range="-0.898845 2.29511"/> -->
            <geom name="rear_right_upper_leg_visual" class="visual" mesh="rear_right_upper_leg_visual" material="yellow"/>
            <geom name="rear_right_upper_leg" type="mesh" mesh="right_upper_leg_collision"/>
            <body name="rear_right_lower_leg" pos="0.025 0 -0.3205" euler="0 -0.3 0">
                <inertial pos="0.00225794 4.6076e-05 -0.180082" quat="0.706982 -0.00596025 -0.00082302 0.707206" mass="0.35" diaginertia="0.00405032 0.00399902 0.00014934"/>
                <!-- <joint name="joint_rear_right_knee" pos="0 0 0" axis="0 1 0" range="-2.7929 -0.2471"/> -->
                <geom name="rear_right_lower_leg_visual" class="visual" mesh="rear_right_lower_leg_visual" material="yellow"/>
                <geom name="rear_right_lower_leg" type="mesh" mesh="right_lower_leg_collision"/>
                <geom size="0.036" pos="0 0 -0.3365"/>
                <site name="site_rear_right" pos="0 0 0" size="0.01"/>
            </body>
        </body>
    </body>
</mujoco>
