<mujoco model="acrobot">
<!-- Copyright (c) 2024 Boston Dynamics AI Institute LLC. All rights reserved. -->

  <asset>
    <texture name="blue_grid" type="2d" builtin="checker" rgb1=".02 .14 .44" rgb2=".27 .55 1" width="300" height="300" mark="edge" markrgb="1 1 1"/>
    <material name="blue_grid" texture="blue_grid" texrepeat="1 1" texuniform="true" reflectance=".2"/>
    <material name="beige" rgba=".7 .5 .3 1"/>
  </asset>

  <option timestep="0.03">
    <flag contact="disable"/>
  </option>

  <worldbody>
    <body name="thigh" pos="0 0 2">
      <joint name="hip" type="hinge" damping="0.1" axis="0 1 0"/>
      <geom name="thigh" fromto="0 0 0 0 0 1" type="capsule" size="0.05" material="beige" mass="1"/>
      <site name="trace_thigh" pos="0 0 1" size="0.01"/>
      <body name="calf" pos="0 0 1">
        <joint name="knee" type="hinge" damping="0.1" axis="0 1 0"/>
        <geom name="calf" fromto="0 0 0 0 0 1" type="capsule" size="0.049" material="beige" mass="1"/>
        <site name="trace_calf" pos="0 0 1" size="0.01"/>
      </body>
    </body>
  </worldbody>

  <actuator>
    <!-- Fixed the hip actuator -->
    <motor name="knee" joint="knee" gear="3" ctrllimited="true" ctrlrange="-1 1"/>
  </actuator>

  <sensor>
    <framepos name="trace_thigh" objtype="site" objname="trace_thigh" />
    <framepos name="trace_calf" objtype="site" objname="trace_calf" />
  </sensor>

</mujoco>
