<mujoco model="allegro_scene">
<!-- Copyright (c) 2023 Boston Dynamics AI Institute LLC. All rights reserved. -->
  <include file="allegro_components/params_and_default.xml" />

  <include file="allegro_components/assets.xml" />

  <worldbody>
    <body>
      <geom mass="0" name="floor" pos="0 0 -2.00" size="10.0 10.0 0.05" rgba="0 1 1 1" type="box"/>
    </body>

    <body name="object" pos="0 0 0" gravcomp="0">
      <freejoint/>
      <site pos="0 0 0" name="site_object"/>
      <geom type="box" mass="0.15" pos="0 0 0" quat="1 0 0 0" size="0.030 0.030 0.030" rgba="0.97 0.85 0.38 1" class="collision"/>
    </body>
  </worldbody>

  <worldbody>
    <body name="palm" quat="0 1 0 1" childclass="allegro_right">
      <inertial mass="0.4154" pos="0 0 0.0475" diaginertia="1e-4 1e-4 1e-4"/>
      <geom class="palm_visual" mesh="base_link"/>
      <geom class="palm_collision"/>
      <joint name="palm_x" axis="0 0 1" class="palm"/>
      <joint name="palm_y" axis="0 -1 0" class="palm"/>

      <include file="allegro_components/fingers.xml" />

    </body>
  </worldbody>

  <include file="allegro_components/contacts_and_sensors.xml" />

  <actuator>
    <position name="palm_x" joint="palm_x" class="palm"/>
    <position name="palm_y" joint="palm_y" class="palm"/>
    <position name="ffa0" joint="ffj0" class="base"/>
    <position name="ffa1" joint="ffj1" class="proximal"/>
    <position name="ffa2" joint="ffj2" class="medial"/>
    <position name="ffa3" joint="ffj3" class="distal"/>
    <position name="mfa0" joint="mfj0" class="base"/>
    <position name="mfa1" joint="mfj1" class="proximal"/>
    <position name="mfa2" joint="mfj2" class="medial"/>
    <position name="mfa3" joint="mfj3" class="distal"/>
    <position name="rfa0" joint="rfj0" class="base"/>
    <position name="rfa1" joint="rfj1" class="proximal"/>
    <position name="rfa2" joint="rfj2" class="medial"/>
    <position name="rfa3" joint="rfj3" class="distal"/>
    <position name="tha0" joint="thj0" class="thumb_base"/>
    <position name="tha1" joint="thj1" class="thumb_proximal"/>
    <position name="tha2" joint="thj2" class="thumb_medial"/>
    <position name="tha3" joint="thj3" class="thumb_distal"/>
  </actuator>

</mujoco>
