<mujoco model="planar_hand">
<!-- Copyright (c) 2023 Boston Dynamics AI Institute LLC. All rights reserved. -->
  <compiler angle="radian" autolimits="true"/>

  <option gravity="0 0 -9.81" timestep="0.01" />

  <asset>
    <texture name="blue_grid" type="2d" builtin="checker" rgb1=".02 .14 .44" rgb2=".27 .55 1" width="300" height="300" mark="edge" markrgb="1 1 1"/>
    <material name="blue_grid" texture="blue_grid" texrepeat="1 1" texuniform="true" reflectance=".2"/>
    <material name="object" rgba=".7 .5 .3 1"/>
    <material name="white" rgba="0.9 .9 .9 1"/>
    <material name="black" rgba="0.1 .1 .1 1"/>
  </asset>

  <default>
    <material specular="0.5" shininess="0.95"/>
    <default class="finger">
      <joint axis="0 1 0" damping="2"/>
      <position kp="25" forcerange="-1000 1000"/>
      <default class="left_shoulder">
        <joint range="-1.57 0"/>
        <position ctrlrange="-1.57 0"/>
      </default>
      <default class="right_shoulder">
        <joint range="0 1.57"/>
        <position ctrlrange="0 1.57"/>
      </default>
      <default class="left_elbow">
        <joint range="-2.4 0"/>
        <position ctrlrange="-2.4 0"/>
      </default>
      <default class="right_elbow">
        <joint range="0 2.4"/>
        <position ctrlrange="0 2.4"/>
      </default>
    </default>
  </default>

  <worldbody>
    <body name="box" pos="0.0 0.0 0.00">
      <geom mass="0.4" size="0.10 0.075 0.15" type="box" material="object"/>
      <geom mass="0" size="0.05 0.01 0.01" pos="0.05 -0.075 0" type="box" rgba="1 0 0 1"/>
      <geom mass="0" size="0.01 0.01 0.05" pos="0.0 -0.075 0.05" type="box" rgba="0 1 0 1"/>
      <site pos="0 0 0" name="site_box"/>
      <joint axis="1 0 0" name="box:slide_object_x" type="slide" range="-5 5"/>
      <joint axis="0 0 1" name="box:slide_object_z" type="slide" range="-5 5"/>
      <joint axis="0 -1 0" name="box:hinge_object_y" type="hinge"/>
    </body>

    <body name="robot_base" pos="0.0 0.0 0.0">
      <geom mass="1.0" pos="0.1 0.0 0.0" quat="0.5 0 0.5 0" size="0.05" type="sphere" material="white"/>
      <geom mass="1.0" pos="-0.1 0.0 0.0" quat="0.5 0 0.5 0" size="0.05" type="sphere" material="white"/>
              <body name="body_left_shoulder" pos="0.10 0 0">
        <geom mass="0.5" pos="0.15 0 0" quat="0.5 0 0.5 0" size="0.05 0.05" type="capsule" material="black"/>
        <site pos="0.15 0 0" name="site_left_shoulder"/>
        <geom mass="0.5" pos="0.30 0 0" quat="0.5 0 0.5 0" size="0.05" type="sphere" material="white"/>
        <joint name="joint_left_shoulder" class="left_shoulder"/>
        <body name="body_left_elbow" pos="0.30 0 0">
          <geom mass="0.5" pos="0.15 0 0" quat="0.5 0 0.5 0" size="0.05 0.05" type="capsule" material="black"/>
          <site pos="0.15 0 0" name="site_left_elbow"/>
          <joint name="joint_left_elbow" class="left_elbow"/>
        </body>
      </body>
      <body name="body_right_shoulder" pos="-0.10 0 0">
        <geom mass="0.5" pos="-0.15 0 0" quat="0.5 0 0.5 0" size="0.05 0.05" type="capsule" material="black"/>
        <site pos="-0.15 0 0" name="site_right_shoulder"/>
        <geom mass="0.5" pos="-0.30 0 0" quat="0.5 0 0.5 0" size="0.05" type="sphere" material="white"/>
        <joint name="joint_right_shoulder" class="right_shoulder"/>
        <body name="body_right_elbow" pos="-0.30 0 0">
          <geom mass="0.5" pos="-0.15 0 0" quat="0.5 0 0.5 0" size="0.05 0.05" type="capsule" material="black"/>
          <site pos="-0.15 0 0" name="site_right_elbow"/>
          <joint name="joint_right_elbow" class="right_elbow"/>
        </body>
      </body>
    </body>
  </worldbody>

  <keyframe>
    <!-- [object_xytheta arm_joint_angles] -->
    <key name="home" qpos="0 0 0  0 0 0 0" />
  </keyframe>

  <sensor>
    <framepos name="sensor_left_thigh" objtype="site" objname="site_left_shoulder" reftype="site" refname="site_box"/>
    <framepos name="sensor_left_calf" objtype="site" objname="site_left_elbow" reftype="site" refname="site_box"/>
    <framepos name="sensor_right_thigh" objtype="site" objname="site_right_shoulder" reftype="site" refname="site_box"/>
    <framepos name="sensor_right_calf" objtype="site" objname="site_right_elbow" reftype="site" refname="site_box"/>
  </sensor>

  <actuator>
    <position name="actuator_left_thigh" joint="joint_left_shoulder" class="left_shoulder"/>
    <position name="actuator_left_calf" joint="joint_left_elbow" class="left_elbow"/>
    <position name="actuator_right_thigh" joint="joint_right_shoulder" class="right_shoulder"/>
    <position name="actuator_right_calf" joint="joint_right_elbow" class="right_elbow"/>
  </actuator>
</mujoco>
