<mujoco model="spot_bimanual">
<!-- Copyright (c) 2023 Boston Dynamics AI Institute LLC. All rights reserved. -->
  <include file="spot_components/params_and_default.xml" />
  <include file="spot_components/assets.xml" />

  <worldbody>
    <geom name="ground" type="plane" size="2 2 0.01" friction="0.7" priority="5" material="blue_grid"/>

    <include file="spot_components/stool.xml" />

    <body name="body_left" pos="0 1.15 0.49" euler="0 0 -1.57">
      <inertial mass="32.86" pos="0 0 0" diaginertia="0.13143999874591827 0.13143999874591827 0.13143999874591827"/>
      <geom name="body_visual_left" class="visual" mesh="body_visual" material="yellow"/>
      <!-- <geom name="body_left" type="mesh" mesh="body"/> -->
      <geom name="body_left" class="collision" type="box" size="0.42 0.11 0.08"/>
      <site name="site_body_left" pos="0 0 0" size="0.01"/>

      <!-- We can deactivate the fixed legs for faster simulation.  -->
      <!-- We'll reactivate them if they are critical. -->
      <!-- <include file="spot_components/fixed_legs.xml" /> -->

      <body name="arm_link_sh0_left" pos="0.292 0 0.188" gravcomp="1">
        <joint name="arm_sh0_left" class="arm_sh0" type="hinge" axis="0 0 1" pos="0 0 0"/>
        <inertial mass="2.3364000000000003" diaginertia="0.009014303010689815 0.005835102417829581 0.00778747846359954" pos="-0.012372709810733795 -4.5211403630673885e-05 -0.02103196457028389" euler="0.0013490340912847287 -0.15433618253071657 0.0066354181456347305" />
        <geom name="arm_link_sh0_visual_left" class="visual" mesh="arm_link_sh0_visual" material="black"/>
        <geom name="arm_link_sh0_base_left" class="collision" type="capsule" size="0.05 0.015" pos="0 0 -0.07"/>
        <geom name="arm_link_sh0_left_motor_left" class="collision" type="sphere" size="0.05" pos="-0.015 -0.062 0" zaxis="0 1 0"/>
        <geom name="arm_link_sh0_right_motor_left" class="collision" type="sphere" size="0.05" pos="-0.015 0.062 0" zaxis="0 1 0"/>
        <site name="site_arm_link_sh0_left" pos="0 0 0" size="0.01"/>

        <body name="arm_link_sh1_left" pos="0 0 0" gravcomp="1">
          <joint name="arm_sh1_left" class="arm_sh1" type="hinge" axis="0 1 0" pos="0 0 0"/>
          <inertial mass="0.2596" diaginertia="6.312631747339145e-10 1.1487063558949979e-08 1.161105128440526e-08" pos="0.17047011852264404 -0.0019251034827902913 4.483893280848861e-05" euler="-0.01179850657706405 0.0002834144901480151 -0.02372295500868482" />
          <geom name="arm_link_sh1_visual_left" class="visual" mesh="arm_link_sh1_visual" material="yellow"/>
          <geom name="arm_link_sh1_base_left" class="collision" type="capsule" size="0.03 0.04" pos="0.03 -0.005 0" zaxis="1 0 0"/>
          <geom name="arm_link_sh1_body_left" class="collision" type="capsule" size="0.04 0.12" pos="0.2 0 0.01" zaxis="1 0 0"/>
          <site name="site_arm_link_sh1_left" pos="0 0 0" size="0.01"/>

          <body name="arm_link_el0_left" pos="0.3385 0 0" gravcomp="1">
            <joint name="arm_el0_left" class="arm_el0" type="hinge" axis="0 1 0" pos="0 0 0"/>
            <inertial mass="0.725" diaginertia="0.0008215365829160558 0.0020047889807066404 0.0019722797759789395" pos="0.0553741455078125 0.00023603376757819206 0.04827198013663292" euler="-0.004185887288594259 -0.6136269547775202 -0.0004619387581783485" />
            <geom name="arm_link_el0_visual_left" class="visual" mesh="arm_link_el0_visual" material="black"/>
            <geom name="arm_link_el0_joint_left" class="collision" type="box" size="0.07 0.04 0.025" pos="0.025 0 0.03" euler= "0 -1 0"/>
            <geom name="arm_link_el0_body_left" class="collision" type="capsule" size="0.04 0.06" pos="0.08 0 0.08" zaxis="1 0 0"/>
            <site name="site_arm_link_el0_left" pos="0 0 0" size="0.01"/>

            <body name="arm_link_el1_left" pos="0.40330 0.0 0.0750" gravcomp="1">
              <joint name="arm_el1_left" class="arm_el1" type="hinge" axis="1 0 0" pos="0 0 0"/>
              <inertial mass="0.725" diaginertia="0.0006254807525240598 0.004402454711936095 0.004515915146038191" pos="-0.1257835328578949 -0.013684478588402271 0.00010157923679798841" euler="-0.15027374227250867 -0.0007874585461915551 0.003728225436950172" />
              <geom name="arm_link_el1_visual_left" class="visual" mesh="arm_link_el1_visual" material="yellow"/>
              <geom name="arm_link_el1_left" class="collision" type="capsule" size="0.04 0.11" pos="-0.15 0 0.005" zaxis="1 0 0"/>
              <site name="site_arm_link_el1_left" pos="0 0 0" size="0.01"/>

              <body name="arm_link_wr0_left" pos="0 0 0" gravcomp="1">
                <joint name="arm_wr0_left" class="arm_wr0" type="hinge" axis="0 1 0" pos="0 0 0"/>
                <inertial mass="0.98" diaginertia="0.0009851320696685427 0.0008916145765810678 0.0012354892751854467" pos="0.008210677653551102 -0.012051000259816647 3.143483627354726e-05" euler="-0.4951534907966386 0.0033720434077784134 0.020027599337697932" />
                <geom name="arm_link_wr0_visual_left" class="visual" mesh="arm_link_wr0_visual" material="black"/>
                <geom name="arm_link_wr0_knob_left" class="collision" type="capsule" size="0.03 0.005" pos="0 -0.05 0" zaxis="0 1 0"/>
                <geom name="arm_link_wr0_main_left" class="collision" type="capsule" size="0.035 0.08" zaxis="1 0 0"/>
                <site name="site_arm_link_wr0_left" pos="0 0 0" size="0.01"/>

                <body name="arm_link_wr1_left" pos="0 0 0" gravcomp="1">
                  <joint name="arm_wr1_left" class="arm_wr1" type="hinge" axis="1 0 0" pos="0 0 0"/>
                  <inertial mass="0.785" diaginertia="0.00076741362048185 0.0017628124054271809 0.0016818105865345951" pos="0.12516802549362183 0.00010137435310753062 -0.013997982256114483" euler="0.006393076449033863 0.2928526604761865 -0.022814984050994802" />
                  <geom name="arm_link_wr1_visual_left" class="visual" mesh="arm_link_wr1_visual" material="yellow"/>
                  <geom name="arm_link_wr1_left" class="collision" type="box" size="0.04 0.042 0.045" pos="0.11 0 -0.0095" />
                  <geom name="bottom_jaw_left" class="collision" type="box" size="0.03 0.025 0.009" pos="0.18 0 -0.045" />
                  <geom name="front_jaw_left" class="collision" type="box" size="0.016 0.015 0.009" pos="0.215 0 -0.045" />
                  <geom name="front_jaw_tooth_left" class="collision" type="box" size="0.005 0.01 0.005" pos="0.224 0 -0.039" euler="0 1 0" />
                  <site name="site_arm_link_wr1_left" pos="0 0 0" size="0.01"/>

                  <body name="arm_link_fngr_left" pos="0.1174 0.0 0.0148" gravcomp="1">
                    <joint name="arm_f1x_left" class="arm_f1x" type="hinge" axis="0 1 0" pos="0 0 0"/>
                    <inertial mass="0.2" diaginertia="0.000144 0.000300 0.000391" pos="0.0478 -0.0002 -0.0163" euler="0.000342 0.375167 -0.004059" />
                    <geom name="arm_link_fngr_visual_left" class="visual" mesh="arm_link_fngr_visual" material="black"/>
                    <geom name="left_jaw_left" class="collision" type="capsule" size="0.022 0.06" pos="0.05 -0.025 -0.015" euler="0.5 2.0 0"/>
                    <geom name="right_jaw_left" class="collision" type="capsule" size="0.022 0.06" pos="0.05 0.025 -0.015" euler="-0.5 2.0 0"/>
                    <site name="site_arm_link_fngr_left" pos="0 0 0" size="0.01"/>
                  </body>
                </body>
              </body>
            </body>
          </body>
        </body>
      </body>
    </body>
    <body name="body_right" pos="0 -1.15 0.49" euler="0 0 1.57">
      <inertial mass="32.86" pos="0 0 0" diaginertia="0.13143999874591827 0.13143999874591827 0.13143999874591827"/>
      <geom name="body_visual_right" class="visual" mesh="body_visual" material="yellow"/>
      <!-- <geom name="body_right" type="mesh" mesh="body"/> -->
      <geom name="body_right" class="collision" type="box" size="0.42 0.11 0.08"/>
      <site name="site_body_right" pos="0 0 0" size="0.01"/>

      <!-- We can deactivate the fixed legs for faster simulation.  -->
      <!-- We'll reactivate them if they are critical. -->
      <!-- <include file="spot_components/fixed_legs.xml" /> -->

      <body name="arm_link_sh0_right" pos="0.292 0 0.188" gravcomp="1">
        <joint name="arm_sh0_right" class="arm_sh0" type="hinge" axis="0 0 1" pos="0 0 0"/>
        <inertial mass="2.3364000000000003" diaginertia="0.009014303010689815 0.005835102417829581 0.00778747846359954" pos="-0.012372709810733795 -4.5211403630673885e-05 -0.02103196457028389" euler="0.0013490340912847287 -0.15433618253071657 0.0066354181456347305" />
        <geom name="arm_link_sh0_visual_right" class="visual" mesh="arm_link_sh0_visual" material="black"/>
        <geom name="arm_link_sh0_base_right" class="collision" type="capsule" size="0.05 0.015" pos="0 0 -0.07"/>
        <geom name="arm_link_sh0_left_motor_right" class="collision" type="sphere" size="0.05" pos="-0.015 -0.062 0" zaxis="0 1 0"/>
        <geom name="arm_link_sh0_right_motor_right" class="collision" type="sphere" size="0.05" pos="-0.015 0.062 0" zaxis="0 1 0"/>
        <site name="site_arm_link_sh0_right" pos="0 0 0" size="0.01"/>

        <body name="arm_link_sh1_right" pos="0 0 0" gravcomp="1">
          <joint name="arm_sh1_right" class="arm_sh1" type="hinge" axis="0 1 0" pos="0 0 0"/>
          <inertial mass="0.2596" diaginertia="6.312631747339145e-10 1.1487063558949979e-08 1.161105128440526e-08" pos="0.17047011852264404 -0.0019251034827902913 4.483893280848861e-05" euler="-0.01179850657706405 0.0002834144901480151 -0.02372295500868482" />
          <geom name="arm_link_sh1_visual_right" class="visual" mesh="arm_link_sh1_visual" material="yellow"/>
          <geom name="arm_link_sh1_base_right" class="collision" type="capsule" size="0.03 0.04" pos="0.03 -0.005 0" zaxis="1 0 0"/>
          <geom name="arm_link_sh1_body_right" class="collision" type="capsule" size="0.04 0.12" pos="0.2 0 0.01" zaxis="1 0 0"/>
          <site name="site_arm_link_sh1_right" pos="0 0 0" size="0.01"/>

          <body name="arm_link_el0_right" pos="0.3385 0 0" gravcomp="1">
            <joint name="arm_el0_right" class="arm_el0" type="hinge" axis="0 1 0" pos="0 0 0"/>
            <inertial mass="0.725" diaginertia="0.0008215365829160558 0.0020047889807066404 0.0019722797759789395" pos="0.0553741455078125 0.00023603376757819206 0.04827198013663292" euler="-0.004185887288594259 -0.6136269547775202 -0.0004619387581783485" />
            <geom name="arm_link_el0_visual_right" class="visual" mesh="arm_link_el0_visual" material="black"/>
            <geom name="arm_link_el0_joint_right" class="collision" type="box" size="0.07 0.04 0.025" pos="0.025 0 0.03" euler= "0 -1 0"/>
            <geom name="arm_link_el0_body_right" class="collision" type="capsule" size="0.04 0.06" pos="0.08 0 0.08" zaxis="1 0 0"/>
            <site name="site_arm_link_el0_right" pos="0 0 0" size="0.01"/>

            <body name="arm_link_el1_right" pos="0.40330 0.0 0.0750" gravcomp="1">
              <joint name="arm_el1_right" class="arm_el1" type="hinge" axis="1 0 0" pos="0 0 0"/>
              <inertial mass="0.725" diaginertia="0.0006254807525240598 0.004402454711936095 0.004515915146038191" pos="-0.1257835328578949 -0.013684478588402271 0.00010157923679798841" euler="-0.15027374227250867 -0.0007874585461915551 0.003728225436950172" />
              <geom name="arm_link_el1_visual_right" class="visual" mesh="arm_link_el1_visual" material="yellow"/>
              <geom name="arm_link_el1_right" class="collision" type="capsule" size="0.04 0.11" pos="-0.15 0 0.005" zaxis="1 0 0"/>
              <site name="site_arm_link_el1_right" pos="0 0 0" size="0.01"/>

              <body name="arm_link_wr0_right" pos="0 0 0" gravcomp="1">
                <joint name="arm_wr0_right" class="arm_wr0" type="hinge" axis="0 1 0" pos="0 0 0"/>
                <inertial mass="0.98" diaginertia="0.0009851320696685427 0.0008916145765810678 0.0012354892751854467" pos="0.008210677653551102 -0.012051000259816647 3.143483627354726e-05" euler="-0.4951534907966386 0.0033720434077784134 0.020027599337697932" />
                <geom name="arm_link_wr0_visual_right" class="visual" mesh="arm_link_wr0_visual" material="black"/>
                <geom name="arm_link_wr0_knob_right" class="collision" type="capsule" size="0.03 0.005" pos="0 -0.05 0" zaxis="0 1 0"/>
                <geom name="arm_link_wr0_main_right" class="collision" type="capsule" size="0.035 0.08" zaxis="1 0 0"/>
                <site name="site_arm_link_wr0_right" pos="0 0 0" size="0.01"/>

                <body name="arm_link_wr1_right" pos="0 0 0" gravcomp="1">
                  <joint name="arm_wr1_right" class="arm_wr1" type="hinge" axis="1 0 0" pos="0 0 0"/>
                  <inertial mass="0.785" diaginertia="0.00076741362048185 0.0017628124054271809 0.0016818105865345951" pos="0.12516802549362183 0.00010137435310753062 -0.013997982256114483" euler="0.006393076449033863 0.2928526604761865 -0.022814984050994802" />
                  <geom name="arm_link_wr1_visual_right" class="visual" mesh="arm_link_wr1_visual" material="yellow"/>
                  <geom name="arm_link_wr1_right" class="collision" type="box" size="0.04 0.042 0.045" pos="0.11 0 -0.0095" />
                  <geom name="bottom_jaw_right" class="collision" type="box" size="0.03 0.025 0.009" pos="0.18 0 -0.045" />
                  <geom name="front_jaw_right" class="collision" type="box" size="0.016 0.015 0.009" pos="0.215 0 -0.045" />
                  <geom name="front_jaw_tooth_right" class="collision" type="box" size="0.005 0.01 0.005" pos="0.224 0 -0.039" euler="0 1 0" />
                  <site name="site_arm_link_wr1_right" pos="0 0 0" size="0.01"/>

                  <body name="arm_link_fngr_right" pos="0.1174 0.0 0.0148" gravcomp="1">
                    <joint name="arm_f1x_right" class="arm_f1x" type="hinge" axis="0 1 0" pos="0 0 0"/>
                    <inertial mass="0.2" diaginertia="0.000144 0.000300 0.000391" pos="0.0478 -0.0002 -0.0163" euler="0.000342 0.375167 -0.004059" />
                    <geom name="arm_link_fngr_visual_right" class="visual" mesh="arm_link_fngr_visual" material="black"/>
                    <geom name="left_jaw_right" class="collision" type="capsule" size="0.022 0.06" pos="0.05 -0.025 -0.015" euler="0.5 2.0 0"/>
                    <geom name="right_jaw_right" class="collision" type="capsule" size="0.022 0.06" pos="0.05 0.025 -0.015" euler="-0.5 2.0 0"/>
                    <site name="site_arm_link_fngr_right" pos="0 0 0" size="0.01"/>
                  </body>
                </body>
              </body>
            </body>
          </body>
        </body>
      </body>
    </body>
  </worldbody>

  <!-- for some reason necessary here but not for floating spot-->
  <contact>
    <exclude body1="body_left" body2="arm_link_sh0_left"/>
    <exclude body1="body_right" body2="arm_link_sh0_right"/>
  </contact>

  <keyframe>
    <!-- mujoco q = [object_xyz, object_q, arm_and_gripper_pos_left, arm_and_gripper_pos_right] -->
    <key name="home" qpos="0 0 0.275  0 0 0 0  0 0 0 0 0 0  0  0 0 0 0 0 0  0" />
  </keyframe>

  <actuator>
    <position name="act_1_left" joint="arm_sh0_left" class="arm_sh0"/>
    <position name="act_2_left" joint="arm_sh1_left" class="arm_sh1"/>
    <position name="act_3_left" joint="arm_el0_left" class="arm_el0"/>
    <position name="act_4_left" joint="arm_el1_left" class="arm_el1"/>
    <position name="act_5_left" joint="arm_wr0_left" class="arm_wr0"/>
    <position name="act_6_left" joint="arm_wr1_left" class="arm_wr1"/>
    <position name="act_7_left" joint="arm_f1x_left" class="arm_f1x"/>

    <position name="act_1_right" joint="arm_sh0_right" class="arm_sh0"/>
    <position name="act_2_right" joint="arm_sh1_right" class="arm_sh1"/>
    <position name="act_3_right" joint="arm_el0_right" class="arm_el0"/>
    <position name="act_4_right" joint="arm_el1_right" class="arm_el1"/>
    <position name="act_5_right" joint="arm_wr0_right" class="arm_wr0"/>
    <position name="act_6_right" joint="arm_wr1_right" class="arm_wr1"/>
    <position name="act_7_right" joint="arm_f1x_right" class="arm_f1x"/>
  </actuator>

  <sensor>
    <framepos name="sensor_body_left" objtype="site" objname="site_body_left" reftype="site" refname="site_object" />
    <framepos name="sensor_arm_link_sh0_left" objtype="site" objname="site_arm_link_sh0_left" reftype="site" refname="site_object" />
    <framepos name="sensor_arm_link_sh1_left" objtype="site" objname="site_arm_link_sh1_left" reftype="site" refname="site_object" />
    <framepos name="sensor_arm_link_el0_left" objtype="site" objname="site_arm_link_el0_left" reftype="site" refname="site_object" />
    <framepos name="sensor_arm_link_el1_left" objtype="site" objname="site_arm_link_el1_left" reftype="site" refname="site_object" />
    <framepos name="sensor_arm_link_wr0_left" objtype="site" objname="site_arm_link_wr0_left" reftype="site" refname="site_object" />
    <framepos name="sensor_arm_link_wr1_left" objtype="site" objname="site_arm_link_wr1_left" reftype="site" refname="site_object" />
    <framepos name="sensor_arm_link_fngr_left" objtype="site" objname="site_arm_link_fngr_left" reftype="site" refname="site_object" />

      <framepos name="sensor_body_right" objtype="site" objname="site_body_right" reftype="site" refname="site_object" />
    <framepos name="sensor_arm_link_sh0_right" objtype="site" objname="site_arm_link_sh0_right" reftype="site" refname="site_object" />
    <framepos name="sensor_arm_link_sh1_right" objtype="site" objname="site_arm_link_sh1_right" reftype="site" refname="site_object" />
    <framepos name="sensor_arm_link_el0_right" objtype="site" objname="site_arm_link_el0_right" reftype="site" refname="site_object" />
    <framepos name="sensor_arm_link_el1_right" objtype="site" objname="site_arm_link_el1_right" reftype="site" refname="site_object" />
    <framepos name="sensor_arm_link_wr0_right" objtype="site" objname="site_arm_link_wr0_right" reftype="site" refname="site_object" />
    <framepos name="sensor_arm_link_wr1_right" objtype="site" objname="site_arm_link_wr1_right" reftype="site" refname="site_object" />
    <framepos name="sensor_arm_link_fngr_right" objtype="site" objname="site_arm_link_fngr_right" reftype="site" refname="site_object" />
  </sensor>
</mujoco>
